{
    "error": {
        "task": "",
        "test_name": "unittest.loader._FailedTest.test_task_id_name_converter",
        "test_description": null,
        "error_type": "error",
        "error_message": "Failed to import test module: test_task_id_name_converter\nTraceback (most recent call last):\n  File \"/usr/local/lib/python3.6/unittest/loader.py\", line 153, in loadTestsFromName\n    module = __import__(module_name)\nModuleNotFoundError: No module named 'py.test_task_id_name_converter'\n",
        "traceback": "ImportError: Failed to import test module: test_task_id_name_converter\nTraceback (most recent call last):\n  File \"/usr/local/lib/python3.6/unittest/loader.py\", line 153, in loadTestsFromName\n    module = __import__(module_name)\nModuleNotFoundError: No module named 'py.test_task_id_name_converter'\n\n",
        "context": {}
    }
}